<?xml version="1.0" ?>
<robot xmlns:xacro="http://www.ros.org/wiki/xacro">

  <xacro:macro name="JOINT_REVOLUTE" params="name axis_xyz origin_rpy origin_xyz parent child ">
    <joint name="${name}" type="revolute">
      <axis xyz="${axis_xyz}" />
      <origin rpy="${origin_rpy}" xyz="${origin_xyz}" />
      <limit effort="1000.0" lower="-3.14" upper="3.14" velocity="0.5"/>
      <parent link="${parent}" />
      <child link="${child}" />
    </joint>
    <transmission name="trans_${name}">
      <type>transmission_interface/SimpleTransmission</type>
      <joint name="${name}">
        <hardwareInterface >hardware_interface/EffortJointInterface</hardwareInterface>
      </joint>
      <actuator name="motor_${name}">
        <hardwareInterface>hardware_interface/EffortJointInterface</hardwareInterface>
        <mechanicalReduction>1</mechanicalReduction>
      </actuator>
    </transmission>
  </xacro:macro>
  <xacro:macro name="JOINT_FIXED" params="name axis_xyz origin_rpy origin_xyz parent child ">
    <joint name="${name}" type="fixed">
      <axis xyz="${axis_xyz}" />
      <origin rpy="${origin_rpy}" xyz="${origin_xyz}" />
      <parent link="${parent}" />
      <child link="${child}" />
    </joint>
  </xacro:macro>

  <xacro:macro name="CYLINDER" params="name origin_xyz origin_rpy radius length">
    <link name="${name}">
      <collision>
        <origin rpy="${origin_rpy}" xyz="${origin_xyz}" />
        <geometry>
          <cylinder radius="${radius}" length="${length}" />
        </geometry>
      </collision>
      <visual>
        <origin rpy="${origin_rpy}" xyz="${origin_xyz}" />
        <geometry>
          <cylinder radius="${radius}" length="${length}" />
        </geometry>
      </visual>
    </link>
  </xacro:macro>

  <xacro:macro name="BOX" params="name origin_xyz origin_rpy size">
    <link name="${name}">
       <inertial>
        <mass value="10" />
        <origin rpy="${origin_rpy}" xyz="${origin_xyz}" />
        <inertia ixx="1" ixy="1" ixz="1" iyy="1" iyz="1" izz="1" />
      </inertial>
      <collision>
        <origin rpy="${origin_rpy}" xyz="${origin_xyz}" />
        <geometry>
          <box size="${size}" />
        </geometry>
      </collision>
      <visual>
        <origin rpy="${origin_rpy}" xyz="${origin_xyz}" />
        <geometry>
          <box size="${size}" />
        </geometry>
      </visual>
    </link>
  </xacro:macro>

  <xacro:macro name="MESH" params="name origin_xyz origin_rpy meshfile meshscale mass ixx ixy ixz iyy iyz izz">
    <link name="${name}">
      <inertial>
        <mass value="${mass}" />
        <origin rpy="${origin_rpy}" xyz="${origin_xyz}" />
        <inertia ixx="${ixx}" ixy="${ixy}" ixz="${ixz}" iyy="${iyy}" iyz="${iyz}" izz="${izz}" />
      </inertial>
      <collision>
        <origin rpy="${origin_rpy}" xyz="${origin_xyz}" />
        <geometry>
          <mesh filename="${meshfile}" scale="${meshscale}"/>
        </geometry>
      </collision>
      <visual>
        <origin rpy="${origin_rpy}" xyz="${origin_xyz}" />
        <geometry>
          <mesh filename="${meshfile}" scale="${meshscale}"/>
        </geometry>
        <material name="light_black"/>
      </visual>
    </link>
  </xacro:macro>

</robot>
