<?xml version="1.0"?>
<robot xmlns:xacro="http://www.ros.org/wiki/xacro">
    <xacro:macro name="LINK" params="linkname x y z roll pitch yaw meshfile mass ixx ixy ixz iyy iyz izz">
        <link name="${linkname}">
            <inertial>
                <origin xyz="${x} ${y} ${z}" rpy="${roll} ${pitch} ${yaw}"/>
                <mass value="${mass}"/>
                <inertia ixx="${ixx}" ixy="${ixy}" ixz="${ixz}" iyy="${iyy}" iyz="${iyz}" izz="${izz}"/>
            </inertial>
            <visual>
                <origin xyz="${x} ${y} ${z}" rpy="${roll} ${pitch} ${yaw}"/>
                <geometry>
                    <mesh filename="${meshfile}" scale="0.001 0.001 0.001"/>
                </geometry>
                <material name="silver">
                    <color rgba="${192/255} ${192/255} ${192/255} 1.0"/>
                </material>
            </visual>
            <collision>
                <origin xyz="${x} ${y} ${z}" rpy="${roll} ${pitch} ${yaw}"/>
                <geometry>
                    <mesh filename="${meshfile}" scale="0.001 0.001 0.001"/>
                </geometry>
            </collision>
        </link>
    </xacro:macro>
    <xacro:macro name="JOINT_REVOLUTE" params="joint_name parent_link child_link x y z roll pitch yaw ax ay az Llimit Ulimit">
        <joint name="${joint_name}" type="revolute">
            <origin xyz="${x} ${y} ${z}" rpy="${roll} ${pitch} ${yaw}"/>
            <parent link="${parent_link}"/>
            <child link="${child_link}"/>
            <axis xyz="${ax} ${ay} ${az}"/>
            <dynamics damping="0.0" friction="0.0"/>
            <limit lower="${Llimit}" upper="${Ulimit}" effort="30" velocity="6.1785"/>
        </joint>
    </xacro:macro>
    <xacro:macro name="GAZEBO_LINK" params="gazebo_colour link">
        <gazebo reference="${link}">
            <material>${gazebo_colour}</material>
            <gravity>true</gravity>
            <selfCollide>true</selfCollide>
            <kp>1000000.0</kp>
            <kd>1.0</kd>
            <mu1>0.8</mu1>
            <mu2>0.8</mu2>
            <maxVel>0.0</maxVel>
            <minDepth>0.001</minDepth>
        </gazebo>
    </xacro:macro>
    <xacro:macro name="TRANSMISSION" params="joint_name">
        <transmission name="${joint_name}_trans">
            <type>transmission_interface/SimpleTransmission</type>
            <joint name="${joint_name}">
                <hardwareInterface>hardware_interface/EffortJointInterface</hardwareInterface>
            </joint>
            <actuator name="${joint_name}_motor">
                <mechanicalReduction>300</mechanicalReduction>
            </actuator>
        </transmission>
    </xacro:macro>
</robot>